Workbook

Sheet Daily_Net_price_movement
A1: Date | B1: Symbol | C1: Week | D1: Close | E1: Next_close_4 | F1: 20day_avg_movement | G1: 25day_avg_movement | H1: 30day_avg_movement | I1: 35day_avg_movement | J1: 40day_avg_movement | K1: 20 day increment (%) | L1: 25 day increment (%) | M1: 30 day increment (%) | N1: 35 day increment (%) | O1: 40 day increment (%) | P1: 20 DAY MOVEMENT | Q1: 25 DAY MOVEMENT | R1: 30 DAY MOVEMENT | S1: 35 DAY MOVEMENT | T1: 40 DAY MOVEMENT
A2: 45016 | B2: RELIANCE.NS | C2: 45012 | D2: 2331.05 | E2: 2324.85 | F2: 2394.3 | G2: 2409.32 | H2: 2415.2933 | I2: 2426.1629 | J2: 2432.2225 | K2: =((F2-E2)/E2) -> 0.029872895 | L2: =((G2-E2)/E2) -> 0.036333527 | M2: =((H2-E2)/E2) -> 0.038902868 | N2: =((I2-E2)/E2) -> 0.043578234 | O2: =((J2-E2)/E2) -> 0.0461847 | P2: =F2>$E2 -> TRUE | Q2: =G2>$E2 -> TRUE | R2: =H2>$E2 -> TRUE | S2: =I2>$E2 -> TRUE | T2: =J2>$E2 -> TRUE
A3: 45110 | B3: RELIANCE.NS | C3: 45110 | D3: 2615.7 | E3: 2633.6 | F3: 2621.65 | G3: 2602.972 | H3: 2594.7167 | I3: 2579.2857 | J3: 2566.3263 | K3: =((F3-E3)/E3) -> -0.0045375152 | L3: =((G3-E3)/E3) -> -0.011629708 | M3: =((H3-E3)/E3) -> -0.014764328 | N3: =((I3-E3)/E3) -> -0.02062359 | O3: =((J3-E3)/E3) -> -0.025544382 | P3: =F3>$E3 -> FALSE | Q3: =G3>$E3 -> FALSE | R3: =H3>$E3 -> FALSE | S3: =I3>$E3 -> FALSE | T3: =J3>$E3 -> FALSE
A4: 45117 | B4: RELIANCE.NS | C4: 45117 | D4: 2735.05 | E4: 2740.7 | F4: 2566.155 | G4: 2563.612 | H4: 2550.7933 | I4: 2538.4606 | K4: =((F4-E4)/E4) -> -0.063686285 | L4: =((G4-E4)/E4) -> -0.06461415 | M4: =((H4-E4)/E4) -> -0.0692913 | N4: =((I4-E4)/E4) -> -0.073791146 | P4: =F4>$E4 -> FALSE | Q4: =G4>$E4 -> FALSE | R4: =H4>$E4 -> FALSE | S4: =I4>$E4 -> FALSE
A5: 44937 | B5: TCS.NS | C5: 44935 | D5: 3328.7 | E5: 3378.4 | F5: 3449.7875 | G5: 3455.792 | H5: 3441.315 | I5: 3428.6329 | J5: 3405.3487 | K5: =((F5-E5)/E5) -> 0.021130565 | L5: =((G5-E5)/E5) -> 0.022907885 | M5: =((H5-E5)/E5) -> 0.018622721 | N5: =((I5-E5)/E5) -> 0.014868831 | O5: =((J5-E5)/E5) -> 0.0079767789 | P5: =F5>$E5 -> TRUE | Q5: =G5>$E5 -> TRUE | R5: =H5>$E5 -> TRUE | S5: =I5>$E5 -> TRUE | T5: =J5>$E5 -> TRUE
A6: 45016 | B6: TCS.NS | C6: 45012 | D6: 3205.9 | E6: 3263.4 | F6: 3194.865 | G6: 3207.026 | H6: 3216.5817 | I6: 3229.8829 | J6: 3236.79 | K6: =((F6-E6)/E6) -> -0.021001103 | L6: =((G6-E6)/E6) -> -0.017274622 | M6: =((H6-E6)/E6) -> -0.014346489 | N6: =((I6-E6)/E6) -> -0.01027062 | O6: =((J6-E6)/E6) -> -0.0081540724 | P6: =F6>$E6 -> FALSE | Q6: =G6>$E6 -> FALSE | R6: =H6>$E6 -> FALSE | S6: =I6>$E6 -> FALSE | T6: =J6>$E6 -> FALSE
A7: 45121 | B7: TCS.NS | C7: 45117 | D7: 3514.65 | E7: 3463.3 | F7: 3423.98 | G7: 3417.228 | H7: 3411.3845 | K7: =((F7-E7)/E7) -> -0.011353334 | L7: =((G7-E7)/E7) -> -0.013302919 | M7: =((H7-E7)/E7) -> -0.014990188 | P7: =F7>$E7 -> FALSE | Q7: =G7>$E7 -> FALSE | R7: =H7>$E7 -> FALSE
A8: 45142 | B8: TCS.NS | C8: 45138 | D8: 3443.55 | E8: 3442.1
A9: 45014 | B9: HDFCBANK.NS | C9: 45012 | D9: 1587.8 | E9: 1666.35 | F9: 1672.6525 | G9: 1669.97 | H9: 1665.2617 | I9: 1659.18 | J9: 1652.4112 | K9: =((F9-E9)/E9) -> 0.0037822186 | L9: =((G9-E9)/E9) -> 0.0021724128 | M9: =((H9-E9)/E9) -> -0.00065312409 | N9: =((I9-E9)/E9) -> -0.0043028175 | O9: =((J9-E9)/E9) -> -0.0083648393 | P9: =F9>$E9 -> TRUE | Q9: =G9>$E9 -> TRUE | R9: =H9>$E9 -> FALSE | S9: =I9>$E9 -> FALSE | T9: =J9>$E9 -> FALSE
A10: 45021 | B10: HDFCBANK.NS | C10: 45019 | D10: 1653.75 | E10: 1684.9 | F10: 1670.975 | G10: 1666.918 | H10: 1659.7467 | I10: 1653.8857 | J10: 1647.92 | K10: =((F10-E10)/E10) -> -0.0082645854 | L10: =((G10-E10)/E10) -> -0.010672443 | M10: =((H10-E10)/E10) -> -0.01492868 | N10: =((I10-E10)/E10) -> -0.018407197 | O10: =((J10-E10)/E10) -> -0.02194789 | P10: =F10>$E10 -> FALSE | Q10: =G10>$E10 -> FALSE | R10: =H10>$E10 -> FALSE | S10: =I10>$E10 -> FALSE | T10: =J10>$E10 -> FALSE
A11: 45098 | B11: HDFCBANK.NS | C11: 45096 | D11: 1635.6 | E11: 1658.6 | F11: 1675.59 | G11: 1671.296 | H11: 1667.1633 | I11: 1659.5414 | J11: 1650.32 | K11: =((F11-E11)/E11) -> 0.010243579 | L11: =((G11-E11)/E11) -> 0.0076546485 | M11: =((H11-E11)/E11) -> 0.0051629889 | N11: =((I11-E11)/E11) -> 0.00056760435 | O11: =((J11-E11)/E11) -> -0.0049921621 | P11: =F11>$E11 -> TRUE | Q11: =G11>$E11 -> TRUE | R11: =H11>$E11 -> TRUE | S11: =I11>$E11 -> TRUE | T11: =J11>$E11 -> FALSE
A12: 45041 | B12: ICICIBANK.NS | C12: 45040 | D12: 913.45 | E12: 922.1 | F12: 941.4125 | G12: 941.62 | H12: 941.205 | I12: 939.58429 | J12: 938.07375 | K12: =((F12-E12)/E12) -> 0.020944041 | L12: =((G12-E12)/E12) -> 0.021169071 | M12: =((H12-E12)/E12) -> 0.020719011 | N12: =((I12-E12)/E12) -> 0.018961377 | O12: =((J12-E12)/E12) -> 0.01732323 | P12: =F12>$E12 -> TRUE | Q12: =G12>$E12 -> TRUE | R12: =H12>$E12 -> TRUE | S12: =I12>$E12 -> TRUE | T12: =J12>$E12 -> TRUE
A13: 45161 | B13: ICICIBANK.NS | C13: 45159 | D13: 966.85 | E13: 967.75
A14: 45057 | B14: HINDUNILVR.NS | C14: 45054 | D14: 2592.4 | E14: 2661.75 | F14: 2661.315 | G14: 2666.704 | H14: 2663.945 | I14: 2671.7286 | J14: 2671.95 | K14: =((F14-E14)/E14) -> -0.00016342632 | L14: =((G14-E14)/E14) -> 0.0018611816 | M14: =((H14-E14)/E14) -> 0.00082464544 | N14: =((I14-E14)/E14) -> 0.0037488763 | O14: =((J14-E14)/E14) -> 0.0038320654 | P14: =F14>$E14 -> FALSE | Q14: =G14>$E14 -> TRUE | R14: =H14>$E14 -> TRUE | S14: =I14>$E14 -> TRUE | T14: =J14>$E14 -> TRUE
A15: 45078 | B15: HINDUNILVR.NS | C15: 45075 | D15: 2697.9 | E15: 2716.2 | F15: 2680.92 | G15: 2679.436 | H15: 2680.0717 | I15: 2665.9343 | J15: 2653.1112 | K15: =((F15-E15)/E15) -> -0.012988734 | L15: =((G15-E15)/E15) -> -0.013535086 | M15: =((H15-E15)/E15) -> -0.013301058 | N15: =((I15-E15)/E15) -> -0.018505896 | O15: =((J15-E15)/E15) -> -0.023226843 | P15: =F15>$E15 -> FALSE | Q15: =G15>$E15 -> FALSE | R15: =H15>$E15 -> FALSE | S15: =I15>$E15 -> FALSE | T15: =J15>$E15 -> FALSE
A16: 44959 | B16: INFY.NS | C16: 44956 | D16: 1583.75 | E16: 1590.5 | F16: 1546.445 | G16: 1523.172 | H16: 1501.9383 | I16: 1486.1957 | J16: 1477.6725 | K16: =((F16-E16)/E16) -> -0.027698837 | L16: =((G16-E16)/E16) -> -0.042331342 | M16: =((H16-E16)/E16) -> -0.055681651 | N16: =((I16-E16)/E16) -> -0.065579557 | O16: =((J16-E16)/E16) -> -0.070938384 | P16: =F16>$E16 -> FALSE | Q16: =G16>$E16 -> FALSE | R16: =H16>$E16 -> FALSE | S16: =I16>$E16 -> FALSE | T16: =J16>$E16 -> FALSE
A17: 45016 | B17: INFY.NS | C17: 45012 | D17: 1427.95 | E17: 1427.6 | F17: 1274.04 | G17: 1270.066 | H17: 1271.935 | I17: 1278.1829 | J17: 1280.6837 | K17: =((F17-E17)/E17) -> -0.10756514 | L17: =((G17-E17)/E17) -> -0.11034884 | M17: =((H17-E17)/E17) -> -0.10903965 | N17: =((I17-E17)/E17) -> -0.10466317 | O17: =((J17-E17)/E17) -> -0.10291135 | P17: =F17>$E17 -> FALSE | Q17: =G17>$E17 -> FALSE | R17: =H17>$E17 -> FALSE | S17: =I17>$E17 -> FALSE | T17: =J17>$E17 -> FALSE
A18: 45068 | B18: INFY.NS | C18: 45068 | D18: 1292.8 | E18: 1317.45 | F18: 1295.76 | G18: 1296.522 | H18: 1303.625 | I18: 1314.4186 | J18: 1326.8125 | K18: =((F18-E18)/E18) -> -0.016463623 | L18: =((G18-E18)/E18) -> -0.015885233 | M18: =((H18-E18)/E18) -> -0.010493757 | N18: =((I18-E18)/E18) -> -0.0023009819 | O18: =((J18-E18)/E18) -> 0.0071065316 | P18: =F18>$E18 -> FALSE | Q18: =G18>$E18 -> FALSE | R18: =H18>$E18 -> FALSE | S18: =I18>$E18 -> FALSE | T18: =J18>$E18 -> TRUE
A19: 45107 | B19: INFY.NS | C19: 45103 | D19: 1335.5 | E19: 1343.9 | F19: 1372.1125 | G19: 1375.492 | H19: 1379.0517 | I19: 1383.7814 | J19: 1388.109 | K19: =((F19-E19)/E19) -> 0.020993005 | L19: =((G19-E19)/E19) -> 0.023507701 | M19: =((H19-E19)/E19) -> 0.02615646 | N19: =((I19-E19)/E19) -> 0.02967589 | O19: =((J19-E19)/E19) -> 0.03289603 | P19: =F19>$E19 -> TRUE | Q19: =G19>$E19 -> TRUE | R19: =H19>$E19 -> TRUE | S19: =I19>$E19 -> TRUE | T19: =J19>$E19 -> TRUE
A20: 44950 | B20: ITC.NS | C20: 44949 | D20: 338.95 | E20: 352.35 | F20: 379.45 | G20: 380.35 | H20: 380.9 | I20: 380.5 | J20: 380.48875 | K20: =((F20-E20)/E20) -> 0.076912161 | L20: =((G20-E20)/E20) -> 0.07946644 | M20: =((H20-E20)/E20) -> 0.081027388 | N20: =((I20-E20)/E20) -> 0.079892153 | O20: =((J20-E20)/E20) -> 0.079860224 | P20: =F20>$E20 -> TRUE | Q20: =G20>$E20 -> TRUE | R20: =H20>$E20 -> TRUE | S20: =I20>$E20 -> TRUE | T20: =J20>$E20 -> TRUE
A21: 45027 | B21: ITC.NS | C21: 45026 | D21: 396 | E21: 398.5 | F21: 419.355 | G21: 420.562 | H21: 424.77667 | I21: 427.25143 | J21: 429.05 | K21: =((F21-E21)/E21) -> 0.052333752 | L21: =((G21-E21)/E21) -> 0.05536261 | M21: =((H21-E21)/E21) -> 0.065938938 | N21: =((I21-E21)/E21) -> 0.072149131 | O21: =((J21-E21)/E21) -> 0.076662484 | P21: =F21>$E21 -> TRUE | Q21: =G21>$E21 -> TRUE | R21: =H21>$E21 -> TRUE | S21: =I21>$E21 -> TRUE | T21: =J21>$E21 -> TRUE
A22: 45037 | B22: ITC.NS | C22: 45033 | D22: 408.25 | E22: 416 | F22: 427.15 | G22: 430.824 | H22: 432.645 | I22: 434.49714 | J22: 436.3325 | K22: =((F22-E22)/E22) -> 0.026802885 | L22: =((G22-E22)/E22) -> 0.035634615 | M22: =((H22-E22)/E22) -> 0.040012019 | N22: =((I22-E22)/E22) -> 0.044464286 | O22: =((J22-E22)/E22) -> 0.048876202 | P22: =F22>$E22 -> TRUE | Q22: =G22>$E22 -> TRUE | R22: =H22>$E22 -> TRUE | S22: =I22>$E22 -> TRUE | T22: =J22>$E22 -> TRUE
A23: 45043 | B23: ITC.NS | C23: 45040 | D23: 416 | E23: 424.6 | F23: 431.2725 | G23: 433.566 | H23: 435.085 | I23: 437.33714 | J23: 438.47625 | K23: =((F23-E23)/E23) -> 0.01571479 | L23: =((G23-E23)/E23) -> 0.021116345 | M23: =((H23-E23)/E23) -> 0.024693829 | N23: =((I23-E23)/E23) -> 0.029997981 | O23: =((J23-E23)/E23) -> 0.032680758 | P23: =F23>$E23 -> TRUE | Q23: =G23>$E23 -> TRUE | R23: =H23>$E23 -> TRUE | S23: =I23>$E23 -> TRUE | T23: =J23>$E23 -> TRUE
A24: 45092 | B24: ITC.NS | C24: 45089 | D24: 448.1 | E24: 447.05 | F24: 464.9475 | G24: 466.414 | H24: 465.84833 | I24: 464.23 | J24: 461.9725 | K24: =((F24-E24)/E24) -> 0.040034672 | L24: =((G24-E24)/E24) -> 0.043315065 | M24: =((H24-E24)/E24) -> 0.042049733 | N24: =((I24-E24)/E24) -> 0.038429706 | O24: =((J24-E24)/E24) -> 0.033379935 | P24: =F24>$E24 -> TRUE | Q24: =G24>$E24 -> TRUE | R24: =H24>$E24 -> TRUE | S24: =I24>$E24 -> TRUE | T24: =J24>$E24 -> TRUE
A25: 45110 | B25: ITC.NS | C25: 45110 | D25: 463.25 | E25: 468.4 | F25: 470.175 | G25: 466.796 | H25: 463.32667 | I25: 461.14714 | J25: 459.54605 | K25: =((F25-E25)/E25) -> 0.0037894962 | L25: =((G25-E25)/E25) -> -0.0034244236 | M25: =((H25-E25)/E25) -> -0.010831198 | N25: =((I25-E25)/E25) -> -0.015484324 | O25: =((J25-E25)/E25) -> -0.018902535 | P25: =F25>$E25 -> TRUE | Q25: =G25>$E25 -> FALSE | R25: =H25>$E25 -> FALSE | S25: =I25>$E25 -> FALSE | T25: =J25>$E25 -> FALSE
... A27: 45110 | B27: SBIN.NS | C27: 45110 | D27: 585.45 | E27: 593.6 | F27: 601.49 | G27: 595.694 | H27: 591.17667 | I27: 588.58429 | J27: 586.94868 | K27: =((F27-E27)/E27) -> 0.013291779 | L27: =((G27-E27)/E27) -> 0.003527628 | M27: =((H27-E27)/E27) -> -0.0040824349 | N27: =((I27-E27)/E27) -> -0.0084496534 | O27: =((J27-E27)/E27) -> -0.011205047 | P27: =F27>$E27 -> TRUE | Q27: =G27>$E27 -> TRUE | R27: =H27>$E27 -> FALSE | S27: =I27>$E27 -> FALSE | T27: =J27>$E27 -> FALSE
A28: 45126 | B28: SBIN.NS | C28: 45124 | D28: 601.45 | E28: 609.6 | F28: 584.6475 | G28: 582.198 | H28: 581.39615 | K28: =((F28-E28)/E28) -> -0.040932579 | L28: =((G28-E28)/E28) -> -0.044950787 | M28: =((H28-E28)/E28) -> -0.046266152 | P28: =F28>$E28 -> FALSE | Q28: =G28>$E28 -> FALSE | R28: =H28>$E28 -> FALSE
A29: 45100 | B29: BHARTIARTL.NS | C29: 45096 | D29: 854.8 | E29: 878.75 | F29: 881.8225 | G29: 882.298 | H29: 882.11 | I29: 879.20571 | J29: 878.2825 | K29: =((F29-E29)/E29) -> 0.0034964438 | L29: =((G29-E29)/E29) -> 0.0040375533 | M29: =((H29-E29)/E29) -> 0.0038236131 | N29: =((I29-E29)/E29) -> 0.00051859378 | O29: =((J29-E29)/E29) -> -0.00053200569 | P29: =F29>$E29 -> TRUE | Q29: =G29>$E29 -> TRUE | R29: =H29>$E29 -> TRUE | S29: =I29>$E29 -> TRUE | T29: =J29>$E29 -> FALSE
A30: 44965 | B30: BAJFINANCE.NS | C30: 44963 | D30: 6351.65 | E30: 6458.7 | F30: 6128.1675 | G30: 6044.236 | H30: 5978.03 | I30: 5948.4286 | J30: 5941.7812 | K30: =((F30-E30)/E30) -> -0.05117632 | L30: =((G30-E30)/E30) -> -0.064171428 | M30: =((H30-E30)/E30) -> -0.074422097 | N30: =((I30-E30)/E30) -> -0.079005284 | O30: =((J30-E30)/E30) -> -0.080034488 | P30: =F30>$E30 -> FALSE | Q30: =G30>$E30 -> FALSE | R30: =H30>$E30 -> FALSE | S30: =I30>$E30 -> FALSE | T30: =J30>$E30 -> FALSE
A31: 45041 | B31: BAJFINANCE.NS | C31: 45040 | D31: 6075.25 | E31: 6249.15 | F31: 6699.925 | G31: 6768.396 | H31: 6820.0517 | I31: 6876.0914 | J31: 6897.6737 | K31: =((F31-E31)/E31) -> 0.07213381 | L31: =((G31-E31)/E31) -> 0.08309066 | M31: =((H31-E31)/E31) -> 0.091356691 | N31: =((I31-E31)/E31) -> 0.10032427 | O31: =((J31-E31)/E31) -> 0.10377791 | P31: =F31>$E31 -> TRUE | Q31: =G31>$E31 -> TRUE | R31: =H31>$E31 -> TRUE | S31: =I31>$E31 -> TRUE | T31: =J31>$E31 -> TRUE
A32: 45054 | B32: BAJFINANCE.NS | C32: 45054 | D32: 6657.95 | E32: 6714.4 | F32: 6907.86 | G32: 6953.932 | H32: 6990.3033 | I32: 7006.8543 | J32: 7096.5238 | K32: =((F32-E32)/E32) -> 0.028812701 | L32: =((G32-E32)/E32) -> 0.035674372 | M32: =((H32-E32)/E32) -> 0.041091286 | N32: =((I32-E32)/E32) -> 0.04355628 | O32: =((J32-E32)/E32) -> 0.056911079 | P32: =F32>$E32 -> TRUE | Q32: =G32>$E32 -> TRUE | R32: =H32>$E32 -> TRUE | S32: =I32>$E32 -> TRUE | T32: =J32>$E32 -> TRUE
A33: 45072 | B33: BAJFINANCE.NS | C33: 45068 | D33: 6904.5 | E33: 7040.5 | F33: 7102.8975 | G33: 7219.15 | H33: 7261.4967 | I33: 7301.1114 | J33: 7320.645 | K33: =((F33-E33)/E33) -> 0.0088626518 | L33: =((G33-E33)/E33) -> 0.025374618 | M33: =((H33-E33)/E33) -> 0.031389343 | N33: =((I33-E33)/E33) -> 0.03701604 | O33: =((J33-E33)/E33) -> 0.039790498 | P33: =F33>$E33 -> TRUE | Q33: =G33>$E33 -> TRUE | R33: =H33>$E33 -> TRUE | S33: =I33>$E33 -> TRUE | T33: =J33>$E33 -> TRUE
A34: 45076 | B34: BAJFINANCE.NS | C34: 45075 | D34: 7005.8 | E34: 7043.2 | F34: 7159.215 | G34: 7255.556 | H34: 7290.2917 | I34: 7333.1386 | J34: 7333.2175 | K34: =((F34-E34)/E34) -> 0.016471916 | L34: =((G34-E34)/E34) -> 0.0301505 | M34: =((H34-E34)/E34) -> 0.035082302 | N34: =((I34-E34)/E34) -> 0.041165744 | O34: =((J34-E34)/E34) -> 0.041176951 | P34: =F34>$E34 -> TRUE | Q34: =G34>$E34 -> TRUE | R34: =H34>$E34 -> TRUE | S34: =I34>$E34 -> TRUE | T34: =J34>$E34 -> TRUE
A35: 45051 | B35: LICI.NS | C35: 45047 | D35: 560.05 | E35: 561 | F35: 588.21 | G35: 590.18 | H35: 596.18 | I35: 599.77429 | J35: 603.1075 | K35: =((F35-E35)/E35) -> 0.048502674 | L35: =((G35-E35)/E35) -> 0.05201426 | M35: =((H35-E35)/E35) -> 0.062709447 | N35: =((I35-E35)/E35) -> 0.069116374 | O35: =((J35-E35)/E35) -> 0.075057932 | P35: =F35>$E35 -> TRUE | Q35: =G35>$E35 -> TRUE | R35: =H35>$E35 -> TRUE | S35: =I35>$E35 -> TRUE | T35: =J35>$E35 -> TRUE
A36: 45096 | B36: LICI.NS | C36: 45096 | D36: 618.3 | E36: 624.95 | F36: 623.0875 | G36: 624.388 | H36: 628.56 | I36: 631.47857 | J36: 634.4375 | K36: =((F36-E36)/E36) -> -0.0029802384 | L36: =((G36-E36)/E36) -> -0.00089927194 | M36: =((H36-E36)/E36) -> 0.0057764621 | N36: =((I36-E36)/E36) -> 0.01044655 | O36: =((J36-E36)/E36) -> 0.015181214 | P36: =F36>$E36 -> FALSE | Q36: =G36>$E36 -> FALSE | R36: =H36>$E36 -> TRUE | S36: =I36>$E36 -> TRUE | T36: =J36>$E36 -> TRUE
A37: 45021 | B37: LT.NS | C37: 45019 | D37: 2257.75 | E37: 2288.5 | F37: 2291.125 | G37: 2275.776 | H37: 2263.8983 | I37: 2257.1514 | J37: 2264.1337 | K37: =((F37-E37)/E37) -> 0.0011470395 | L37: =((G37-E37)/E37) -> -0.0055599738 | M37: =((H37-E37)/E37) -> -0.010750127 | N37: =((I37-E37)/E37) -> -0.013698305 | O37: =((J37-E37)/E37) -> -0.010647258 | P37: =F37>$E37 -> TRUE | Q37: =G37>$E37 -> FALSE | R37: =H37>$E37 -> FALSE | S37: =I37>$E37 -> FALSE | T37: =J37>$E37 -> FALSE
A38: 45082 | B38: LT.NS | C38: 45082 | D38: 2268.3 | E38: 2363 | F38: 2405.935 | G38: 2417.576 | H38: 2436.315 | I38: 2465.3629 | J38: 2485.935 | K38: =((F38-E38)/E38) -> 0.0181697 | L38: =((G38-E38)/E38) -> 0.023096064 | M38: =((H38-E38)/E38) -> 0.031026238 | N38: =((I38-E38)/E38) -> 0.043319025 | O38: =((J38-E38)/E38) -> 0.052024968 | P38: =F38>$E38 -> TRUE | Q38: =G38>$E38 -> TRUE | R38: =H38>$E38 -> TRUE | S38: =I38>$E38 -> TRUE | T38: =J38>$E38 -> TRUE
A39: 45107 | B39: LT.NS | C39: 45103 | D39: 2475.55 | E39: 2488.6 | F39: 2547.2 | G39: 2565.364 | H39: 2580.6 | I39: 2594.3771 | J39: 2605.8769 | K39: =((F39-E39)/E39) -> 0.023547376 | L39: =((G39-E39)/E39) -> 0.030846259 | M39: =((H39-E39)/E39) -> 0.036968577 | N39: =((I39-E39)/E39) -> 0.042504678 | O39: =((J39-E39)/E39) -> 0.047125662 | P39: =F39>$E39 -> TRUE | Q39: =G39>$E39 -> TRUE | R39: =H39>$E39 -> TRUE | S39: =I39>$E39 -> TRUE | T39: =J39>$E39 -> TRUE
A40: 45128 | B40: LT.NS | C40: 45124 | D40: 2586.25 | E40: 2660.2 | F40: 2653.85 | G40: 2662.625 | K40: =((F40-E40)/E40) -> -0.0023870386 | L40: =((G40-E40)/E40) -> 0.0009115856 | P40: =F40>$E40 -> FALSE | Q40: =G40>$E40 -> TRUE
A41: 44935 | B41: HCLTECH.NS | C41: 44935 | D41: 1067.45 | E41: 1077.8 | F41: 1125.7625 | G41: 1125.08 | H41: 1119.9317 | I41: 1117.9514 | J41: 1116.6137 | K41: =((F41-E41)/E41) -> 0.044500371 | L41: =((G41-E41)/E41) -> 0.043867137 | M41: =((H41-E41)/E41) -> 0.039090431 | N41: =((I41-E41)/E41) -> 0.037253135 | O41: =((J41-E41)/E41) -> 0.036012015 | P41: =F41>$E41 -> TRUE | Q41: =G41>$E41 -> TRUE | R41: =H41>$E41 -> TRUE | S41: =I41>$E41 -> TRUE | T41: =J41>$E41 -> TRUE
...

Sheet Price movement analysis
C3: AVG. NET PRICE MOVEMENT ANALYSIS
A5: METRICS | B5: 20 DAYS AVG. MOVEMENT | C5: 25 DAYS AVG. MOVEMENT | D5: 30 DAYS AVG. MOVEMENT | E5: 35 DAYS AVG. MOVEMENT | F5: 40 DAYS AVG. MOVEMENT
A6: TOTAL COUNT | B6: =COUNTA(Daily_Net_price_movement!P$2:P$346) -> 318 | C6: =COUNTA(Daily_Net_price_movement!Q$2:Q$346) -> 310 | D6: =COUNTA(Daily_Net_price_movement!R$2:R$346) -> 302 | E6: =COUNTA(Daily_Net_price_movement!S$2:S$346) -> 294 | F6: =COUNTA(Daily_Net_price_movement!T$2:T$346) -> 287
A7: INCREMENT (Num) | B7: =COUNTIF(Daily_Net_price_movement!P$2:P$346,"TRUE") -> 201 | C7: =COUNTIF(Daily_Net_price_movement!Q$2:Q$346,"TRUE") -> 199 | D7: =COUNTIF(Daily_Net_price_movement!R$2:R$346,"TRUE") -> 194 | E7: =COUNTIF(Daily_Net_price_movement!S$2:S$346,"TRUE") -> 193 | F7: =COUNTIF(Daily_Net_price_movement!T$2:T$346,"TRUE") -> 193
A8: DECREMENT (Num) | B8: =COUNTIF(Daily_Net_price_movement!P$3:P$347,"FALSE") -> 117 | C8: =COUNTIF(Daily_Net_price_movement!Q$3:Q$347,"FALSE") -> 111 | D8: =COUNTIF(Daily_Net_price_movement!R$3:R$347,"FALSE") -> 108 | E8: =COUNTIF(Daily_Net_price_movement!S$3:S$347,"FALSE") -> 101 | F8: =COUNTIF(Daily_Net_price_movement!T$3:T$347,"FALSE") -> 94
A9: INCREMENT (%) | B9: =B7/B6 -> 0.63207547 | C9: =C7/C6 -> 0.64193548 | D9: =D7/D6 -> 0.64238411 | E9: =E7/E6 -> 0.65646258 | F9: =F7/F6 -> 0.67247387
A10: % DECREMENT | B10: =B8/B6 -> 0.36792453 | C10: =C8/C6 -> 0.35806452 | D10: =D8/D6 -> 0.35761589 | E10: =E8/E6 -> 0.34353742 | F10: =F8/F6 -> 0.32752613
A11: AVG. MOVEMENT(%) | B11: =AVERAGE(Daily_Net_price_movement!K2:K346) -> 0.008136946 | C11: =AVERAGE(Daily_Net_price_movement!L2:L346) -> 0.011279085 | D11: =AVERAGE(Daily_Net_price_movement!M2:M346) -> 0.014468456 | E11: =AVERAGE(Daily_Net_price_movement!N2:N346) -> 0.018569249 | F11: =AVERAGE(Daily_Net_price_movement!O2:O346) -> 0.02191273
A12: AVG % INCREMENT (%) | B12: =AVERAGEIF(Daily_Net_price_movement!P$2:P$346,"TRUE",Daily_Net_price_movement!K$2:K$346) -> 0.031631364 | C12: =AVERAGEIF(Daily_Net_price_movement!Q$2:Q$346,"TRUE",Daily_Net_price_movement!L$2:L$346) -> 0.037158997 | D12: =AVERAGEIF(Daily_Net_price_movement!R$2:R$346,"TRUE",Daily_Net_price_movement!M$2:M$346) -> 0.042092799 | E12: =AVERAGEIF(Daily_Net_price_movement!S$2:S$346,"TRUE",Daily_Net_price_movement!N$2:N$346) -> 0.047177973 | F12: =AVERAGEIF(Daily_Net_price_movement!T$2:T$346,"TRUE",Daily_Net_price_movement!O$2:O$346) -> 0.05137797
A13: AVG % DECREMENT (%) | B13: =AVERAGEIF(Daily_Net_price_movement!P$3:P$347,"FALSE",Daily_Net_price_movement!K$3:K$347) -> -0.032225258 | C13: =AVERAGEIF(Daily_Net_price_movement!Q$3:Q$347,"FALSE",Daily_Net_price_movement!L$3:L$347) -> -0.035118233 | D13: =AVERAGEIF(Daily_Net_price_movement!R$3:R$347,"FALSE",Daily_Net_price_movement!M$3:M$347) -> -0.035153049 | E13: =AVERAGEIF(Daily_Net_price_movement!S$3:S$347,"FALSE",Daily_Net_price_movement!N$3:N$347) -> -0.036098908 | F13: =AVERAGEIF(Daily_Net_price_movement!T$3:T$347,"FALSE",Daily_Net_price_movement!O$3:O$347) -> -0.038585051
A14: Max. Upward movement(%) | B14: =MAX(Daily_Net_price_movement!K$2:K$346) -> 0.14058493 | C14: =MAX(Daily_Net_price_movement!L$2:L$346) -> 0.15538364 | D14: =MAX(Daily_Net_price_movement!M$2:M$346) -> 0.17194433 | E14: =MAX(Daily_Net_price_movement!N$2:N$346) -> 0.17428087 | F14: =MAX(Daily_Net_price_movement!O$2:O$346) -> 0.18526516
A15: Worst down movement (%) | B15: =MIN(Daily_Net_price_movement!K$3:K$347) -> -0.47954039 | C15: =MIN(Daily_Net_price_movement!L$3:L$347) -> -0.53165317 | D15: =MIN(Daily_Net_price_movement!M$3:M$347) -> -0.56446902 | E15: =MIN(Daily_Net_price_movement!N$3:N$347) -> -0.57787725 | F15: =MIN(Daily_Net_price_movement!O$3:O$347) -> -0.57909179
D18: SUMMARY TABLE
A20: =A5 -> METRICS | B20: =B5 -> 20 DAYS AVG. MOVEMENT | C20: =C5 -> 25 DAYS AVG. MOVEMENT | D20: =D5 -> 30 DAYS AVG. MOVEMENT | E20: =E5 -> 35 DAYS AVG. MOVEMENT | F20: =F5 -> 40 DAYS AVG. MOVEMENT
A21: =A11 -> AVG. MOVEMENT(%) | B21: =B11 -> 0.008136946 | C21: =C11 -> 0.011279085 | D21: =D11 -> 0.014468456 | E21: =E11 -> 0.018569249 | F21: =F11 -> 0.02191273
A22: =A14 -> Max. Upward movement(%) | B22: =B14 -> 0.14058493 | C22: =C14 -> 0.15538364 | D22: =D14 -> 0.17194433 | E22: =E14 -> 0.17428087 | F22: =F14 -> 0.18526516
A23: =A15 -> Worst down movement (%) | B23: =B15 -> -0.47954039 | C23: =C15 -> -0.53165317 | D23: =D15 -> -0.56446902 | E23: =E15 -> -0.57787725 | F23: =F15 -> -0.57909179
